{
 "cells": [
  {
   "cell_type": "code",
   "execution_count": null,
   "id": "fbdd323a",
   "metadata": {},
   "outputs": [],
   "source": [
    "+ /"
   ]
  },
  {
   "cell_type": "code",
   "execution_count": null,
   "id": "2d6fede1",
   "metadata": {},
   "outputs": [],
   "source": [
    "x = 10\n",
    "y = 4.2\n",
    "num = 10.0\n",
    "\n"
   ]
  },
  {
   "cell_type": "code",
   "execution_count": 5,
   "id": "fb8cd9ac",
   "metadata": {
    "scrolled": true
   },
   "outputs": [
    {
     "name": "stdout",
     "output_type": "stream",
     "text": [
      "False True False\n"
     ]
    }
   ],
   "source": [
    "x = 10\n",
    "y = 4.2\n",
    "\n",
    "num = 10.0\n",
    "\n",
    "print(num > x*y, num <= x + y, num*y != x*y)"
   ]
  },
  {
   "cell_type": "code",
   "execution_count": 2,
   "id": "faaaf996",
   "metadata": {},
   "outputs": [
    {
     "data": {
      "text/plain": [
       "True"
      ]
     },
     "execution_count": 2,
     "metadata": {},
     "output_type": "execute_result"
    }
   ],
   "source": [
    "x == num"
   ]
  },
  {
   "cell_type": "code",
   "execution_count": 4,
   "id": "354b91ed",
   "metadata": {
    "scrolled": true
   },
   "outputs": [
    {
     "ename": "NameError",
     "evalue": "name 'numy' is not defined",
     "output_type": "error",
     "traceback": [
      "\u001b[1;31m---------------------------------------------------------------------------\u001b[0m",
      "\u001b[1;31mNameError\u001b[0m                                 Traceback (most recent call last)",
      "\u001b[1;32m<ipython-input-4-fa61f5299dc6>\u001b[0m in \u001b[0;36m<module>\u001b[1;34m\u001b[0m\n\u001b[1;32m----> 1\u001b[1;33m \u001b[0mnumy\u001b[0m\u001b[1;33m\u001b[0m\u001b[1;33m\u001b[0m\u001b[0m\n\u001b[0m",
      "\u001b[1;31mNameError\u001b[0m: name 'numy' is not defined"
     ]
    }
   ],
   "source": [
    "numy"
   ]
  },
  {
   "cell_type": "code",
   "execution_count": 6,
   "id": "dd5d67da",
   "metadata": {},
   "outputs": [
    {
     "data": {
      "text/plain": [
       "False"
      ]
     },
     "execution_count": 6,
     "metadata": {},
     "output_type": "execute_result"
    }
   ],
   "source": [
    "x = 4.2\n",
    "y = 10\n",
    "z = \"42\"\n",
    "\n",
    "not (((x * y == z) and not (x < y)) or y % 2 == 0)"
   ]
  },
  {
   "cell_type": "code",
   "execution_count": 7,
   "id": "ec26497b",
   "metadata": {},
   "outputs": [
    {
     "data": {
      "text/plain": [
       "True"
      ]
     },
     "execution_count": 7,
     "metadata": {},
     "output_type": "execute_result"
    }
   ],
   "source": [
    "not(not(x < y and x*y == z)) or (x >= y or y%2 == 0)"
   ]
  },
  {
   "cell_type": "code",
   "execution_count": 8,
   "id": "b2978c54",
   "metadata": {},
   "outputs": [
    {
     "data": {
      "text/plain": [
       "False"
      ]
     },
     "execution_count": 8,
     "metadata": {},
     "output_type": "execute_result"
    }
   ],
   "source": [
    "False and True"
   ]
  },
  {
   "cell_type": "code",
   "execution_count": 10,
   "id": "f372eee6",
   "metadata": {},
   "outputs": [
    {
     "name": "stdout",
     "output_type": "stream",
     "text": [
      "2.0\n"
     ]
    }
   ],
   "source": [
    "cont = 0\n",
    "resultado = 0\n",
    "n = 1000\n",
    "\n",
    "teste = 0\n",
    "\n",
    "while cont != n:\n",
    "    resultado = resultado + 1/(2**cont)\n",
    "    cont = cont + 1\n",
    "    teste = teste + 1\n",
    "\n",
    "print(resultado)"
   ]
  },
  {
   "cell_type": "code",
   "execution_count": 11,
   "id": "40893ea3",
   "metadata": {},
   "outputs": [
    {
     "data": {
      "text/plain": [
       "1000"
      ]
     },
     "execution_count": 11,
     "metadata": {},
     "output_type": "execute_result"
    }
   ],
   "source": [
    "teste"
   ]
  },
  {
   "cell_type": "code",
   "execution_count": 14,
   "id": "5fe9ad7c",
   "metadata": {},
   "outputs": [],
   "source": [
    "def f_it(n):\n",
    "    resultado = 1\n",
    "\n",
    "    for i in range(1, n+1, 1):\n",
    "        resultado = resultado * i\n",
    "  \n",
    "    return resultado"
   ]
  },
  {
   "cell_type": "code",
   "execution_count": 21,
   "id": "5b8e92fa",
   "metadata": {},
   "outputs": [],
   "source": [
    "def f_rec(n):\n",
    "    if n != 0:\n",
    "        return n*f_rec(n-1)\n",
    "    return 1"
   ]
  },
  {
   "cell_type": "code",
   "execution_count": null,
   "id": "f46f55fb",
   "metadata": {},
   "outputs": [
    {
     "name": "stderr",
     "output_type": "stream",
     "text": [
      "ERROR:root:Internal Python error in the inspect module.\n",
      "Below is the traceback from this internal error.\n",
      "\n",
      "ERROR:root:Internal Python error in the inspect module.\n",
      "Below is the traceback from this internal error.\n",
      "\n"
     ]
    },
    {
     "name": "stdout",
     "output_type": "stream",
     "text": [
      "Traceback (most recent call last):\n",
      "  File \"C:\\Users\\alece\\miniconda3\\envs\\torch\\lib\\site-packages\\IPython\\core\\interactiveshell.py\", line 3437, in run_code\n",
      "    exec(code_obj, self.user_global_ns, self.user_ns)\n",
      "  File \"<ipython-input-23-9a463484ce7b>\", line 1, in <module>\n",
      "    f_rec(-10)\n",
      "  File \"<ipython-input-21-5624afb31009>\", line 3, in f_rec\n",
      "    return n*f_rec(n-1)\n",
      "  File \"<ipython-input-21-5624afb31009>\", line 3, in f_rec\n",
      "    return n*f_rec(n-1)\n",
      "  File \"<ipython-input-21-5624afb31009>\", line 3, in f_rec\n",
      "    return n*f_rec(n-1)\n",
      "  [Previous line repeated 2952 more times]\n",
      "  File \"<ipython-input-21-5624afb31009>\", line 2, in f_rec\n",
      "    if n != 0:\n",
      "RecursionError: maximum recursion depth exceeded in comparison\n",
      "\n",
      "During handling of the above exception, another exception occurred:\n",
      "\n",
      "Traceback (most recent call last):\n",
      "  File \"C:\\Users\\alece\\miniconda3\\envs\\torch\\lib\\site-packages\\IPython\\core\\interactiveshell.py\", line 2061, in showtraceback\n",
      "    stb = value._render_traceback_()\n",
      "AttributeError: 'RecursionError' object has no attribute '_render_traceback_'\n",
      "\n",
      "During handling of the above exception, another exception occurred:\n",
      "\n",
      "Traceback (most recent call last):\n",
      "  File \"C:\\Users\\alece\\miniconda3\\envs\\torch\\lib\\genericpath.py\", line 19, in exists\n",
      "    os.stat(path)\n",
      "OSError: [WinError 123] The filename, directory name, or volume label syntax is incorrect: '<ipython-input-21-5624afb31009>'\n",
      "\n",
      "During handling of the above exception, another exception occurred:\n",
      "\n",
      "Traceback (most recent call last):\n",
      "  File \"C:\\Users\\alece\\miniconda3\\envs\\torch\\lib\\site-packages\\IPython\\core\\ultratb.py\", line 1101, in get_records\n",
      "    return _fixed_getinnerframes(etb, number_of_lines_of_context, tb_offset)\n",
      "  File \"C:\\Users\\alece\\miniconda3\\envs\\torch\\lib\\site-packages\\IPython\\core\\ultratb.py\", line 248, in wrapped\n",
      "    return f(*args, **kwargs)\n",
      "  File \"C:\\Users\\alece\\miniconda3\\envs\\torch\\lib\\site-packages\\IPython\\core\\ultratb.py\", line 281, in _fixed_getinnerframes\n",
      "    records = fix_frame_records_filenames(inspect.getinnerframes(etb, context))\n",
      "  File \"C:\\Users\\alece\\miniconda3\\envs\\torch\\lib\\inspect.py\", line 1502, in getinnerframes\n",
      "    frameinfo = (tb.tb_frame,) + getframeinfo(tb, context)\n",
      "  File \"C:\\Users\\alece\\miniconda3\\envs\\torch\\lib\\inspect.py\", line 1464, in getframeinfo\n",
      "    lines, lnum = findsource(frame)\n",
      "  File \"C:\\Users\\alece\\miniconda3\\envs\\torch\\lib\\site-packages\\IPython\\core\\ultratb.py\", line 170, in findsource\n",
      "    file = getsourcefile(object) or getfile(object)\n",
      "  File \"C:\\Users\\alece\\miniconda3\\envs\\torch\\lib\\inspect.py\", line 693, in getsourcefile\n",
      "    if os.path.exists(filename):\n",
      "  File \"C:\\Users\\alece\\miniconda3\\envs\\torch\\lib\\genericpath.py\", line 19, in exists\n",
      "    os.stat(path)\n",
      "KeyboardInterrupt\n",
      "Traceback (most recent call last):\n",
      "  File \"C:\\Users\\alece\\miniconda3\\envs\\torch\\lib\\site-packages\\IPython\\core\\interactiveshell.py\", line 3437, in run_code\n",
      "    exec(code_obj, self.user_global_ns, self.user_ns)\n",
      "  File \"<ipython-input-23-9a463484ce7b>\", line 1, in <module>\n",
      "    f_rec(-10)\n",
      "  File \"<ipython-input-21-5624afb31009>\", line 3, in f_rec\n",
      "    return n*f_rec(n-1)\n",
      "  File \"<ipython-input-21-5624afb31009>\", line 3, in f_rec\n",
      "    return n*f_rec(n-1)\n",
      "  File \"<ipython-input-21-5624afb31009>\", line 3, in f_rec\n",
      "    return n*f_rec(n-1)\n",
      "  [Previous line repeated 2952 more times]\n",
      "  File \"<ipython-input-21-5624afb31009>\", line 2, in f_rec\n",
      "    if n != 0:\n",
      "RecursionError: maximum recursion depth exceeded in comparison\n",
      "\n",
      "During handling of the above exception, another exception occurred:\n",
      "\n",
      "Traceback (most recent call last):\n",
      "  File \"C:\\Users\\alece\\miniconda3\\envs\\torch\\lib\\site-packages\\IPython\\core\\interactiveshell.py\", line 2061, in showtraceback\n",
      "    stb = value._render_traceback_()\n",
      "AttributeError: 'RecursionError' object has no attribute '_render_traceback_'\n",
      "\n",
      "During handling of the above exception, another exception occurred:\n",
      "\n",
      "Traceback (most recent call last):\n",
      "  File \"C:\\Users\\alece\\miniconda3\\envs\\torch\\lib\\site-packages\\IPython\\core\\interactiveshell.py\", line 3357, in run_ast_nodes\n",
      "    if (await self.run_code(code, result,  async_=asy)):\n",
      "  File \"C:\\Users\\alece\\miniconda3\\envs\\torch\\lib\\site-packages\\IPython\\core\\interactiveshell.py\", line 3454, in run_code\n",
      "    self.showtraceback(running_compiled_code=True)\n",
      "  File \"C:\\Users\\alece\\miniconda3\\envs\\torch\\lib\\site-packages\\IPython\\core\\interactiveshell.py\", line 2064, in showtraceback\n",
      "    value, tb, tb_offset=tb_offset)\n",
      "  File \"C:\\Users\\alece\\miniconda3\\envs\\torch\\lib\\site-packages\\IPython\\core\\ultratb.py\", line 1368, in structured_traceback\n",
      "    self, etype, value, tb, tb_offset, number_of_lines_of_context)\n",
      "  File \"C:\\Users\\alece\\miniconda3\\envs\\torch\\lib\\site-packages\\IPython\\core\\ultratb.py\", line 1268, in structured_traceback\n",
      "    self, etype, value, tb, tb_offset, number_of_lines_of_context\n",
      "  File \"C:\\Users\\alece\\miniconda3\\envs\\torch\\lib\\site-packages\\IPython\\core\\ultratb.py\", line 1125, in structured_traceback\n",
      "    tb_offset)\n",
      "  File \"C:\\Users\\alece\\miniconda3\\envs\\torch\\lib\\site-packages\\IPython\\core\\ultratb.py\", line 1082, in format_exception_as_a_whole\n",
      "    last_unique, recursion_repeat = find_recursion(orig_etype, evalue, records)\n",
      "  File \"C:\\Users\\alece\\miniconda3\\envs\\torch\\lib\\site-packages\\IPython\\core\\ultratb.py\", line 381, in find_recursion\n",
      "    if not is_recursion_error(etype, value, records):\n",
      "  File \"C:\\Users\\alece\\miniconda3\\envs\\torch\\lib\\site-packages\\IPython\\core\\ultratb.py\", line 368, in is_recursion_error\n",
      "    and len(records) > _FRAME_RECURSION_LIMIT\n",
      "TypeError: object of type 'NoneType' has no len()\n",
      "\n",
      "During handling of the above exception, another exception occurred:\n",
      "\n",
      "Traceback (most recent call last):\n",
      "  File \"C:\\Users\\alece\\miniconda3\\envs\\torch\\lib\\site-packages\\IPython\\core\\interactiveshell.py\", line 2061, in showtraceback\n",
      "    stb = value._render_traceback_()\n",
      "AttributeError: 'TypeError' object has no attribute '_render_traceback_'\n",
      "\n",
      "During handling of the above exception, another exception occurred:\n",
      "\n",
      "Traceback (most recent call last):\n",
      "  File \"C:\\Users\\alece\\miniconda3\\envs\\torch\\lib\\genericpath.py\", line 19, in exists\n",
      "    os.stat(path)\n",
      "OSError: [WinError 123] The filename, directory name, or volume label syntax is incorrect: '<ipython-input-21-5624afb31009>'\n",
      "\n",
      "During handling of the above exception, another exception occurred:\n",
      "\n",
      "Traceback (most recent call last):\n",
      "  File \"C:\\Users\\alece\\miniconda3\\envs\\torch\\lib\\site-packages\\IPython\\core\\ultratb.py\", line 1101, in get_records\n",
      "    return _fixed_getinnerframes(etb, number_of_lines_of_context, tb_offset)\n",
      "  File \"C:\\Users\\alece\\miniconda3\\envs\\torch\\lib\\site-packages\\IPython\\core\\ultratb.py\", line 248, in wrapped\n",
      "    return f(*args, **kwargs)\n",
      "  File \"C:\\Users\\alece\\miniconda3\\envs\\torch\\lib\\site-packages\\IPython\\core\\ultratb.py\", line 281, in _fixed_getinnerframes\n",
      "    records = fix_frame_records_filenames(inspect.getinnerframes(etb, context))\n",
      "  File \"C:\\Users\\alece\\miniconda3\\envs\\torch\\lib\\inspect.py\", line 1502, in getinnerframes\n",
      "    frameinfo = (tb.tb_frame,) + getframeinfo(tb, context)\n",
      "  File \"C:\\Users\\alece\\miniconda3\\envs\\torch\\lib\\inspect.py\", line 1460, in getframeinfo\n",
      "    filename = getsourcefile(frame) or getfile(frame)\n",
      "  File \"C:\\Users\\alece\\miniconda3\\envs\\torch\\lib\\inspect.py\", line 693, in getsourcefile\n",
      "    if os.path.exists(filename):\n",
      "  File \"C:\\Users\\alece\\miniconda3\\envs\\torch\\lib\\genericpath.py\", line 19, in exists\n",
      "    os.stat(path)\n",
      "KeyboardInterrupt\n"
     ]
    },
    {
     "name": "stderr",
     "output_type": "stream",
     "text": [
      "ERROR:root:Internal Python error in the inspect module.\n",
      "Below is the traceback from this internal error.\n",
      "\n"
     ]
    },
    {
     "name": "stdout",
     "output_type": "stream",
     "text": [
      "Traceback (most recent call last):\n",
      "  File \"C:\\Users\\alece\\miniconda3\\envs\\torch\\lib\\site-packages\\IPython\\core\\interactiveshell.py\", line 3437, in run_code\n",
      "    exec(code_obj, self.user_global_ns, self.user_ns)\n",
      "  File \"<ipython-input-23-9a463484ce7b>\", line 1, in <module>\n",
      "    f_rec(-10)\n",
      "  File \"<ipython-input-21-5624afb31009>\", line 3, in f_rec\n",
      "    return n*f_rec(n-1)\n",
      "  File \"<ipython-input-21-5624afb31009>\", line 3, in f_rec\n",
      "    return n*f_rec(n-1)\n",
      "  File \"<ipython-input-21-5624afb31009>\", line 3, in f_rec\n",
      "    return n*f_rec(n-1)\n",
      "  [Previous line repeated 2952 more times]\n",
      "  File \"<ipython-input-21-5624afb31009>\", line 2, in f_rec\n",
      "    if n != 0:\n",
      "RecursionError: maximum recursion depth exceeded in comparison\n",
      "\n",
      "During handling of the above exception, another exception occurred:\n",
      "\n",
      "Traceback (most recent call last):\n",
      "  File \"C:\\Users\\alece\\miniconda3\\envs\\torch\\lib\\site-packages\\IPython\\core\\interactiveshell.py\", line 2061, in showtraceback\n",
      "    stb = value._render_traceback_()\n",
      "AttributeError: 'RecursionError' object has no attribute '_render_traceback_'\n",
      "\n",
      "During handling of the above exception, another exception occurred:\n",
      "\n",
      "Traceback (most recent call last):\n",
      "  File \"C:\\Users\\alece\\miniconda3\\envs\\torch\\lib\\site-packages\\IPython\\core\\interactiveshell.py\", line 3357, in run_ast_nodes\n",
      "    if (await self.run_code(code, result,  async_=asy)):\n",
      "  File \"C:\\Users\\alece\\miniconda3\\envs\\torch\\lib\\site-packages\\IPython\\core\\interactiveshell.py\", line 3454, in run_code\n",
      "    self.showtraceback(running_compiled_code=True)\n",
      "  File \"C:\\Users\\alece\\miniconda3\\envs\\torch\\lib\\site-packages\\IPython\\core\\interactiveshell.py\", line 2064, in showtraceback\n",
      "    value, tb, tb_offset=tb_offset)\n",
      "  File \"C:\\Users\\alece\\miniconda3\\envs\\torch\\lib\\site-packages\\IPython\\core\\ultratb.py\", line 1368, in structured_traceback\n",
      "    self, etype, value, tb, tb_offset, number_of_lines_of_context)\n",
      "  File \"C:\\Users\\alece\\miniconda3\\envs\\torch\\lib\\site-packages\\IPython\\core\\ultratb.py\", line 1268, in structured_traceback\n",
      "    self, etype, value, tb, tb_offset, number_of_lines_of_context\n",
      "  File \"C:\\Users\\alece\\miniconda3\\envs\\torch\\lib\\site-packages\\IPython\\core\\ultratb.py\", line 1125, in structured_traceback\n",
      "    tb_offset)\n",
      "  File \"C:\\Users\\alece\\miniconda3\\envs\\torch\\lib\\site-packages\\IPython\\core\\ultratb.py\", line 1082, in format_exception_as_a_whole\n",
      "    last_unique, recursion_repeat = find_recursion(orig_etype, evalue, records)\n",
      "  File \"C:\\Users\\alece\\miniconda3\\envs\\torch\\lib\\site-packages\\IPython\\core\\ultratb.py\", line 381, in find_recursion\n",
      "    if not is_recursion_error(etype, value, records):\n",
      "  File \"C:\\Users\\alece\\miniconda3\\envs\\torch\\lib\\site-packages\\IPython\\core\\ultratb.py\", line 368, in is_recursion_error\n",
      "    and len(records) > _FRAME_RECURSION_LIMIT\n",
      "TypeError: object of type 'NoneType' has no len()\n",
      "\n",
      "During handling of the above exception, another exception occurred:\n",
      "\n",
      "Traceback (most recent call last):\n",
      "  File \"C:\\Users\\alece\\miniconda3\\envs\\torch\\lib\\site-packages\\IPython\\core\\interactiveshell.py\", line 2061, in showtraceback\n",
      "    stb = value._render_traceback_()\n",
      "AttributeError: 'TypeError' object has no attribute '_render_traceback_'\n",
      "\n",
      "During handling of the above exception, another exception occurred:\n",
      "\n",
      "Traceback (most recent call last):\n",
      "  File \"C:\\Users\\alece\\miniconda3\\envs\\torch\\lib\\site-packages\\IPython\\core\\interactiveshell.py\", line 2940, in _run_cell\n",
      "    return runner(coro)\n",
      "  File \"C:\\Users\\alece\\miniconda3\\envs\\torch\\lib\\site-packages\\IPython\\core\\async_helpers.py\", line 68, in _pseudo_sync_runner\n",
      "    coro.send(None)\n",
      "  File \"C:\\Users\\alece\\miniconda3\\envs\\torch\\lib\\site-packages\\IPython\\core\\interactiveshell.py\", line 3166, in run_cell_async\n",
      "    interactivity=interactivity, compiler=compiler, result=result)\n",
      "  File \"C:\\Users\\alece\\miniconda3\\envs\\torch\\lib\\site-packages\\IPython\\core\\interactiveshell.py\", line 3376, in run_ast_nodes\n",
      "    self.showtraceback()\n",
      "  File \"C:\\Users\\alece\\miniconda3\\envs\\torch\\lib\\site-packages\\IPython\\core\\interactiveshell.py\", line 2064, in showtraceback\n",
      "    value, tb, tb_offset=tb_offset)\n",
      "  File \"C:\\Users\\alece\\miniconda3\\envs\\torch\\lib\\site-packages\\IPython\\core\\ultratb.py\", line 1368, in structured_traceback\n",
      "    self, etype, value, tb, tb_offset, number_of_lines_of_context)\n",
      "  File \"C:\\Users\\alece\\miniconda3\\envs\\torch\\lib\\site-packages\\IPython\\core\\ultratb.py\", line 1268, in structured_traceback\n",
      "    self, etype, value, tb, tb_offset, number_of_lines_of_context\n",
      "  File \"C:\\Users\\alece\\miniconda3\\envs\\torch\\lib\\site-packages\\IPython\\core\\ultratb.py\", line 1143, in structured_traceback\n",
      "    chained_exceptions_tb_offset)\n",
      "  File \"C:\\Users\\alece\\miniconda3\\envs\\torch\\lib\\site-packages\\IPython\\core\\ultratb.py\", line 1082, in format_exception_as_a_whole\n",
      "    last_unique, recursion_repeat = find_recursion(orig_etype, evalue, records)\n",
      "  File \"C:\\Users\\alece\\miniconda3\\envs\\torch\\lib\\site-packages\\IPython\\core\\ultratb.py\", line 381, in find_recursion\n",
      "    if not is_recursion_error(etype, value, records):\n",
      "  File \"C:\\Users\\alece\\miniconda3\\envs\\torch\\lib\\site-packages\\IPython\\core\\ultratb.py\", line 368, in is_recursion_error\n",
      "    and len(records) > _FRAME_RECURSION_LIMIT\n",
      "TypeError: object of type 'NoneType' has no len()\n",
      "\n",
      "During handling of the above exception, another exception occurred:\n",
      "\n",
      "Traceback (most recent call last):\n",
      "  File \"C:\\Users\\alece\\miniconda3\\envs\\torch\\lib\\site-packages\\IPython\\core\\interactiveshell.py\", line 2061, in showtraceback\n",
      "    stb = value._render_traceback_()\n",
      "AttributeError: 'TypeError' object has no attribute '_render_traceback_'\n",
      "\n",
      "During handling of the above exception, another exception occurred:\n",
      "\n",
      "Traceback (most recent call last):\n",
      "  File \"C:\\Users\\alece\\miniconda3\\envs\\torch\\lib\\genericpath.py\", line 19, in exists\n",
      "    os.stat(path)\n",
      "OSError: [WinError 123] The filename, directory name, or volume label syntax is incorrect: '<ipython-input-21-5624afb31009>'\n",
      "\n",
      "During handling of the above exception, another exception occurred:\n",
      "\n",
      "Traceback (most recent call last):\n",
      "  File \"C:\\Users\\alece\\miniconda3\\envs\\torch\\lib\\site-packages\\IPython\\core\\ultratb.py\", line 1101, in get_records\n",
      "    return _fixed_getinnerframes(etb, number_of_lines_of_context, tb_offset)\n",
      "  File \"C:\\Users\\alece\\miniconda3\\envs\\torch\\lib\\site-packages\\IPython\\core\\ultratb.py\", line 248, in wrapped\n",
      "    return f(*args, **kwargs)\n",
      "  File \"C:\\Users\\alece\\miniconda3\\envs\\torch\\lib\\site-packages\\IPython\\core\\ultratb.py\", line 281, in _fixed_getinnerframes\n",
      "    records = fix_frame_records_filenames(inspect.getinnerframes(etb, context))\n",
      "  File \"C:\\Users\\alece\\miniconda3\\envs\\torch\\lib\\inspect.py\", line 1502, in getinnerframes\n",
      "    frameinfo = (tb.tb_frame,) + getframeinfo(tb, context)\n",
      "  File \"C:\\Users\\alece\\miniconda3\\envs\\torch\\lib\\inspect.py\", line 1464, in getframeinfo\n",
      "    lines, lnum = findsource(frame)\n",
      "  File \"C:\\Users\\alece\\miniconda3\\envs\\torch\\lib\\site-packages\\IPython\\core\\ultratb.py\", line 170, in findsource\n",
      "    file = getsourcefile(object) or getfile(object)\n",
      "  File \"C:\\Users\\alece\\miniconda3\\envs\\torch\\lib\\inspect.py\", line 693, in getsourcefile\n",
      "    if os.path.exists(filename):\n",
      "  File \"C:\\Users\\alece\\miniconda3\\envs\\torch\\lib\\genericpath.py\", line 19, in exists\n",
      "    os.stat(path)\n",
      "KeyboardInterrupt\n"
     ]
    }
   ],
   "source": [
    "f_rec(-10)"
   ]
  },
  {
   "cell_type": "code",
   "execution_count": 23,
   "id": "21c5f5b7",
   "metadata": {},
   "outputs": [
    {
     "name": "stdout",
     "output_type": "stream",
     "text": [
      "ERROR! Session/line number was not unique in database. History logging moved to new session 836\n"
     ]
    }
   ],
   "source": [
    "def f_rec(n):\n",
    "    if n == 0:\n",
    "        return 1\n",
    "    return n*f_rec(n-1)"
   ]
  },
  {
   "cell_type": "code",
   "execution_count": null,
   "id": "cf7ddb82",
   "metadata": {},
   "outputs": [
    {
     "name": "stderr",
     "output_type": "stream",
     "text": [
      "ERROR:root:Internal Python error in the inspect module.\n",
      "Below is the traceback from this internal error.\n",
      "\n",
      "ERROR:root:Internal Python error in the inspect module.\n",
      "Below is the traceback from this internal error.\n",
      "\n"
     ]
    },
    {
     "name": "stdout",
     "output_type": "stream",
     "text": [
      "Traceback (most recent call last):\n",
      "  File \"C:\\Users\\alece\\miniconda3\\envs\\torch\\lib\\site-packages\\IPython\\core\\interactiveshell.py\", line 3437, in run_code\n",
      "    exec(code_obj, self.user_global_ns, self.user_ns)\n",
      "  File \"<ipython-input-24-9a463484ce7b>\", line 1, in <module>\n",
      "    f_rec(-10)\n",
      "  File \"<ipython-input-23-d95411b47805>\", line 4, in f_rec\n",
      "    return n*f_rec(n-1)\n",
      "  File \"<ipython-input-23-d95411b47805>\", line 4, in f_rec\n",
      "    return n*f_rec(n-1)\n",
      "  File \"<ipython-input-23-d95411b47805>\", line 4, in f_rec\n",
      "    return n*f_rec(n-1)\n",
      "  [Previous line repeated 2952 more times]\n",
      "  File \"<ipython-input-23-d95411b47805>\", line 2, in f_rec\n",
      "    if n == 0:\n",
      "RecursionError: maximum recursion depth exceeded in comparison\n",
      "\n",
      "During handling of the above exception, another exception occurred:\n",
      "\n",
      "Traceback (most recent call last):\n",
      "  File \"C:\\Users\\alece\\miniconda3\\envs\\torch\\lib\\site-packages\\IPython\\core\\interactiveshell.py\", line 2061, in showtraceback\n",
      "    stb = value._render_traceback_()\n",
      "AttributeError: 'RecursionError' object has no attribute '_render_traceback_'\n",
      "\n",
      "During handling of the above exception, another exception occurred:\n",
      "\n",
      "Traceback (most recent call last):\n",
      "  File \"C:\\Users\\alece\\miniconda3\\envs\\torch\\lib\\genericpath.py\", line 19, in exists\n",
      "    os.stat(path)\n",
      "OSError: [WinError 123] The filename, directory name, or volume label syntax is incorrect: '<ipython-input-23-d95411b47805>'\n",
      "\n",
      "During handling of the above exception, another exception occurred:\n",
      "\n",
      "Traceback (most recent call last):\n",
      "  File \"C:\\Users\\alece\\miniconda3\\envs\\torch\\lib\\site-packages\\IPython\\core\\ultratb.py\", line 1101, in get_records\n",
      "    return _fixed_getinnerframes(etb, number_of_lines_of_context, tb_offset)\n",
      "  File \"C:\\Users\\alece\\miniconda3\\envs\\torch\\lib\\site-packages\\IPython\\core\\ultratb.py\", line 248, in wrapped\n",
      "    return f(*args, **kwargs)\n",
      "  File \"C:\\Users\\alece\\miniconda3\\envs\\torch\\lib\\site-packages\\IPython\\core\\ultratb.py\", line 281, in _fixed_getinnerframes\n",
      "    records = fix_frame_records_filenames(inspect.getinnerframes(etb, context))\n",
      "  File \"C:\\Users\\alece\\miniconda3\\envs\\torch\\lib\\inspect.py\", line 1502, in getinnerframes\n",
      "    frameinfo = (tb.tb_frame,) + getframeinfo(tb, context)\n",
      "  File \"C:\\Users\\alece\\miniconda3\\envs\\torch\\lib\\inspect.py\", line 1464, in getframeinfo\n",
      "    lines, lnum = findsource(frame)\n",
      "  File \"C:\\Users\\alece\\miniconda3\\envs\\torch\\lib\\site-packages\\IPython\\core\\ultratb.py\", line 170, in findsource\n",
      "    file = getsourcefile(object) or getfile(object)\n",
      "  File \"C:\\Users\\alece\\miniconda3\\envs\\torch\\lib\\inspect.py\", line 693, in getsourcefile\n",
      "    if os.path.exists(filename):\n",
      "  File \"C:\\Users\\alece\\miniconda3\\envs\\torch\\lib\\genericpath.py\", line 19, in exists\n",
      "    os.stat(path)\n",
      "KeyboardInterrupt\n",
      "Traceback (most recent call last):\n",
      "  File \"C:\\Users\\alece\\miniconda3\\envs\\torch\\lib\\site-packages\\IPython\\core\\interactiveshell.py\", line 3437, in run_code\n",
      "    exec(code_obj, self.user_global_ns, self.user_ns)\n",
      "  File \"<ipython-input-24-9a463484ce7b>\", line 1, in <module>\n",
      "    f_rec(-10)\n",
      "  File \"<ipython-input-23-d95411b47805>\", line 4, in f_rec\n",
      "    return n*f_rec(n-1)\n",
      "  File \"<ipython-input-23-d95411b47805>\", line 4, in f_rec\n",
      "    return n*f_rec(n-1)\n",
      "  File \"<ipython-input-23-d95411b47805>\", line 4, in f_rec\n",
      "    return n*f_rec(n-1)\n",
      "  [Previous line repeated 2952 more times]\n",
      "  File \"<ipython-input-23-d95411b47805>\", line 2, in f_rec\n",
      "    if n == 0:\n",
      "RecursionError: maximum recursion depth exceeded in comparison\n",
      "\n",
      "During handling of the above exception, another exception occurred:\n",
      "\n",
      "Traceback (most recent call last):\n",
      "  File \"C:\\Users\\alece\\miniconda3\\envs\\torch\\lib\\site-packages\\IPython\\core\\interactiveshell.py\", line 2061, in showtraceback\n",
      "    stb = value._render_traceback_()\n",
      "AttributeError: 'RecursionError' object has no attribute '_render_traceback_'\n",
      "\n",
      "During handling of the above exception, another exception occurred:\n",
      "\n",
      "Traceback (most recent call last):\n",
      "  File \"C:\\Users\\alece\\miniconda3\\envs\\torch\\lib\\site-packages\\IPython\\core\\interactiveshell.py\", line 3357, in run_ast_nodes\n",
      "    if (await self.run_code(code, result,  async_=asy)):\n",
      "  File \"C:\\Users\\alece\\miniconda3\\envs\\torch\\lib\\site-packages\\IPython\\core\\interactiveshell.py\", line 3454, in run_code\n",
      "    self.showtraceback(running_compiled_code=True)\n",
      "  File \"C:\\Users\\alece\\miniconda3\\envs\\torch\\lib\\site-packages\\IPython\\core\\interactiveshell.py\", line 2064, in showtraceback\n",
      "    value, tb, tb_offset=tb_offset)\n",
      "  File \"C:\\Users\\alece\\miniconda3\\envs\\torch\\lib\\site-packages\\IPython\\core\\ultratb.py\", line 1368, in structured_traceback\n",
      "    self, etype, value, tb, tb_offset, number_of_lines_of_context)\n",
      "  File \"C:\\Users\\alece\\miniconda3\\envs\\torch\\lib\\site-packages\\IPython\\core\\ultratb.py\", line 1268, in structured_traceback\n",
      "    self, etype, value, tb, tb_offset, number_of_lines_of_context\n",
      "  File \"C:\\Users\\alece\\miniconda3\\envs\\torch\\lib\\site-packages\\IPython\\core\\ultratb.py\", line 1125, in structured_traceback\n",
      "    tb_offset)\n",
      "  File \"C:\\Users\\alece\\miniconda3\\envs\\torch\\lib\\site-packages\\IPython\\core\\ultratb.py\", line 1082, in format_exception_as_a_whole\n",
      "    last_unique, recursion_repeat = find_recursion(orig_etype, evalue, records)\n",
      "  File \"C:\\Users\\alece\\miniconda3\\envs\\torch\\lib\\site-packages\\IPython\\core\\ultratb.py\", line 381, in find_recursion\n",
      "    if not is_recursion_error(etype, value, records):\n",
      "  File \"C:\\Users\\alece\\miniconda3\\envs\\torch\\lib\\site-packages\\IPython\\core\\ultratb.py\", line 368, in is_recursion_error\n",
      "    and len(records) > _FRAME_RECURSION_LIMIT\n",
      "TypeError: object of type 'NoneType' has no len()\n",
      "\n",
      "During handling of the above exception, another exception occurred:\n",
      "\n",
      "Traceback (most recent call last):\n",
      "  File \"C:\\Users\\alece\\miniconda3\\envs\\torch\\lib\\site-packages\\IPython\\core\\interactiveshell.py\", line 2061, in showtraceback\n",
      "    stb = value._render_traceback_()\n",
      "AttributeError: 'TypeError' object has no attribute '_render_traceback_'\n",
      "\n",
      "During handling of the above exception, another exception occurred:\n",
      "\n",
      "Traceback (most recent call last):\n",
      "  File \"C:\\Users\\alece\\miniconda3\\envs\\torch\\lib\\genericpath.py\", line 19, in exists\n",
      "    os.stat(path)\n",
      "OSError: [WinError 123] The filename, directory name, or volume label syntax is incorrect: '<ipython-input-23-d95411b47805>'\n",
      "\n",
      "During handling of the above exception, another exception occurred:\n",
      "\n",
      "Traceback (most recent call last):\n",
      "  File \"C:\\Users\\alece\\miniconda3\\envs\\torch\\lib\\site-packages\\IPython\\core\\ultratb.py\", line 1101, in get_records\n",
      "    return _fixed_getinnerframes(etb, number_of_lines_of_context, tb_offset)\n",
      "  File \"C:\\Users\\alece\\miniconda3\\envs\\torch\\lib\\site-packages\\IPython\\core\\ultratb.py\", line 248, in wrapped\n",
      "    return f(*args, **kwargs)\n",
      "  File \"C:\\Users\\alece\\miniconda3\\envs\\torch\\lib\\site-packages\\IPython\\core\\ultratb.py\", line 281, in _fixed_getinnerframes\n",
      "    records = fix_frame_records_filenames(inspect.getinnerframes(etb, context))\n",
      "  File \"C:\\Users\\alece\\miniconda3\\envs\\torch\\lib\\inspect.py\", line 1502, in getinnerframes\n",
      "    frameinfo = (tb.tb_frame,) + getframeinfo(tb, context)\n",
      "  File \"C:\\Users\\alece\\miniconda3\\envs\\torch\\lib\\inspect.py\", line 1464, in getframeinfo\n",
      "    lines, lnum = findsource(frame)\n",
      "  File \"C:\\Users\\alece\\miniconda3\\envs\\torch\\lib\\site-packages\\IPython\\core\\ultratb.py\", line 170, in findsource\n",
      "    file = getsourcefile(object) or getfile(object)\n",
      "  File \"C:\\Users\\alece\\miniconda3\\envs\\torch\\lib\\inspect.py\", line 693, in getsourcefile\n",
      "    if os.path.exists(filename):\n",
      "  File \"C:\\Users\\alece\\miniconda3\\envs\\torch\\lib\\genericpath.py\", line 19, in exists\n",
      "    os.stat(path)\n",
      "KeyboardInterrupt\n"
     ]
    },
    {
     "name": "stderr",
     "output_type": "stream",
     "text": [
      "ERROR:root:Internal Python error in the inspect module.\n",
      "Below is the traceback from this internal error.\n",
      "\n"
     ]
    },
    {
     "name": "stdout",
     "output_type": "stream",
     "text": [
      "Traceback (most recent call last):\n",
      "  File \"C:\\Users\\alece\\miniconda3\\envs\\torch\\lib\\site-packages\\IPython\\core\\interactiveshell.py\", line 3437, in run_code\n",
      "    exec(code_obj, self.user_global_ns, self.user_ns)\n",
      "  File \"<ipython-input-24-9a463484ce7b>\", line 1, in <module>\n",
      "    f_rec(-10)\n",
      "  File \"<ipython-input-23-d95411b47805>\", line 4, in f_rec\n",
      "    return n*f_rec(n-1)\n",
      "  File \"<ipython-input-23-d95411b47805>\", line 4, in f_rec\n",
      "    return n*f_rec(n-1)\n",
      "  File \"<ipython-input-23-d95411b47805>\", line 4, in f_rec\n",
      "    return n*f_rec(n-1)\n",
      "  [Previous line repeated 2952 more times]\n",
      "  File \"<ipython-input-23-d95411b47805>\", line 2, in f_rec\n",
      "    if n == 0:\n",
      "RecursionError: maximum recursion depth exceeded in comparison\n",
      "\n",
      "During handling of the above exception, another exception occurred:\n",
      "\n",
      "Traceback (most recent call last):\n",
      "  File \"C:\\Users\\alece\\miniconda3\\envs\\torch\\lib\\site-packages\\IPython\\core\\interactiveshell.py\", line 2061, in showtraceback\n",
      "    stb = value._render_traceback_()\n",
      "AttributeError: 'RecursionError' object has no attribute '_render_traceback_'\n",
      "\n",
      "During handling of the above exception, another exception occurred:\n",
      "\n",
      "Traceback (most recent call last):\n",
      "  File \"C:\\Users\\alece\\miniconda3\\envs\\torch\\lib\\site-packages\\IPython\\core\\interactiveshell.py\", line 3357, in run_ast_nodes\n",
      "    if (await self.run_code(code, result,  async_=asy)):\n",
      "  File \"C:\\Users\\alece\\miniconda3\\envs\\torch\\lib\\site-packages\\IPython\\core\\interactiveshell.py\", line 3454, in run_code\n",
      "    self.showtraceback(running_compiled_code=True)\n",
      "  File \"C:\\Users\\alece\\miniconda3\\envs\\torch\\lib\\site-packages\\IPython\\core\\interactiveshell.py\", line 2064, in showtraceback\n",
      "    value, tb, tb_offset=tb_offset)\n",
      "  File \"C:\\Users\\alece\\miniconda3\\envs\\torch\\lib\\site-packages\\IPython\\core\\ultratb.py\", line 1368, in structured_traceback\n",
      "    self, etype, value, tb, tb_offset, number_of_lines_of_context)\n",
      "  File \"C:\\Users\\alece\\miniconda3\\envs\\torch\\lib\\site-packages\\IPython\\core\\ultratb.py\", line 1268, in structured_traceback\n",
      "    self, etype, value, tb, tb_offset, number_of_lines_of_context\n",
      "  File \"C:\\Users\\alece\\miniconda3\\envs\\torch\\lib\\site-packages\\IPython\\core\\ultratb.py\", line 1125, in structured_traceback\n",
      "    tb_offset)\n",
      "  File \"C:\\Users\\alece\\miniconda3\\envs\\torch\\lib\\site-packages\\IPython\\core\\ultratb.py\", line 1082, in format_exception_as_a_whole\n",
      "    last_unique, recursion_repeat = find_recursion(orig_etype, evalue, records)\n",
      "  File \"C:\\Users\\alece\\miniconda3\\envs\\torch\\lib\\site-packages\\IPython\\core\\ultratb.py\", line 381, in find_recursion\n",
      "    if not is_recursion_error(etype, value, records):\n",
      "  File \"C:\\Users\\alece\\miniconda3\\envs\\torch\\lib\\site-packages\\IPython\\core\\ultratb.py\", line 368, in is_recursion_error\n",
      "    and len(records) > _FRAME_RECURSION_LIMIT\n",
      "TypeError: object of type 'NoneType' has no len()\n",
      "\n",
      "During handling of the above exception, another exception occurred:\n",
      "\n",
      "Traceback (most recent call last):\n",
      "  File \"C:\\Users\\alece\\miniconda3\\envs\\torch\\lib\\site-packages\\IPython\\core\\interactiveshell.py\", line 2061, in showtraceback\n",
      "    stb = value._render_traceback_()\n",
      "AttributeError: 'TypeError' object has no attribute '_render_traceback_'\n",
      "\n",
      "During handling of the above exception, another exception occurred:\n",
      "\n",
      "Traceback (most recent call last):\n",
      "  File \"C:\\Users\\alece\\miniconda3\\envs\\torch\\lib\\site-packages\\IPython\\core\\interactiveshell.py\", line 2940, in _run_cell\n",
      "    return runner(coro)\n",
      "  File \"C:\\Users\\alece\\miniconda3\\envs\\torch\\lib\\site-packages\\IPython\\core\\async_helpers.py\", line 68, in _pseudo_sync_runner\n",
      "    coro.send(None)\n",
      "  File \"C:\\Users\\alece\\miniconda3\\envs\\torch\\lib\\site-packages\\IPython\\core\\interactiveshell.py\", line 3166, in run_cell_async\n",
      "    interactivity=interactivity, compiler=compiler, result=result)\n",
      "  File \"C:\\Users\\alece\\miniconda3\\envs\\torch\\lib\\site-packages\\IPython\\core\\interactiveshell.py\", line 3376, in run_ast_nodes\n",
      "    self.showtraceback()\n",
      "  File \"C:\\Users\\alece\\miniconda3\\envs\\torch\\lib\\site-packages\\IPython\\core\\interactiveshell.py\", line 2064, in showtraceback\n",
      "    value, tb, tb_offset=tb_offset)\n",
      "  File \"C:\\Users\\alece\\miniconda3\\envs\\torch\\lib\\site-packages\\IPython\\core\\ultratb.py\", line 1368, in structured_traceback\n",
      "    self, etype, value, tb, tb_offset, number_of_lines_of_context)\n",
      "  File \"C:\\Users\\alece\\miniconda3\\envs\\torch\\lib\\site-packages\\IPython\\core\\ultratb.py\", line 1268, in structured_traceback\n",
      "    self, etype, value, tb, tb_offset, number_of_lines_of_context\n",
      "  File \"C:\\Users\\alece\\miniconda3\\envs\\torch\\lib\\site-packages\\IPython\\core\\ultratb.py\", line 1143, in structured_traceback\n",
      "    chained_exceptions_tb_offset)\n",
      "  File \"C:\\Users\\alece\\miniconda3\\envs\\torch\\lib\\site-packages\\IPython\\core\\ultratb.py\", line 1082, in format_exception_as_a_whole\n",
      "    last_unique, recursion_repeat = find_recursion(orig_etype, evalue, records)\n",
      "  File \"C:\\Users\\alece\\miniconda3\\envs\\torch\\lib\\site-packages\\IPython\\core\\ultratb.py\", line 381, in find_recursion\n",
      "    if not is_recursion_error(etype, value, records):\n",
      "  File \"C:\\Users\\alece\\miniconda3\\envs\\torch\\lib\\site-packages\\IPython\\core\\ultratb.py\", line 368, in is_recursion_error\n",
      "    and len(records) > _FRAME_RECURSION_LIMIT\n",
      "TypeError: object of type 'NoneType' has no len()\n",
      "\n",
      "During handling of the above exception, another exception occurred:\n",
      "\n",
      "Traceback (most recent call last):\n",
      "  File \"C:\\Users\\alece\\miniconda3\\envs\\torch\\lib\\site-packages\\IPython\\core\\interactiveshell.py\", line 2061, in showtraceback\n",
      "    stb = value._render_traceback_()\n",
      "AttributeError: 'TypeError' object has no attribute '_render_traceback_'\n",
      "\n",
      "During handling of the above exception, another exception occurred:\n",
      "\n",
      "Traceback (most recent call last):\n",
      "  File \"C:\\Users\\alece\\miniconda3\\envs\\torch\\lib\\genericpath.py\", line 19, in exists\n",
      "    os.stat(path)\n",
      "OSError: [WinError 123] The filename, directory name, or volume label syntax is incorrect: '<ipython-input-23-d95411b47805>'\n",
      "\n",
      "During handling of the above exception, another exception occurred:\n",
      "\n",
      "Traceback (most recent call last):\n",
      "  File \"C:\\Users\\alece\\miniconda3\\envs\\torch\\lib\\site-packages\\IPython\\core\\ultratb.py\", line 1101, in get_records\n",
      "    return _fixed_getinnerframes(etb, number_of_lines_of_context, tb_offset)\n",
      "  File \"C:\\Users\\alece\\miniconda3\\envs\\torch\\lib\\site-packages\\IPython\\core\\ultratb.py\", line 248, in wrapped\n",
      "    return f(*args, **kwargs)\n",
      "  File \"C:\\Users\\alece\\miniconda3\\envs\\torch\\lib\\site-packages\\IPython\\core\\ultratb.py\", line 281, in _fixed_getinnerframes\n",
      "    records = fix_frame_records_filenames(inspect.getinnerframes(etb, context))\n",
      "  File \"C:\\Users\\alece\\miniconda3\\envs\\torch\\lib\\inspect.py\", line 1502, in getinnerframes\n",
      "    frameinfo = (tb.tb_frame,) + getframeinfo(tb, context)\n",
      "  File \"C:\\Users\\alece\\miniconda3\\envs\\torch\\lib\\inspect.py\", line 1460, in getframeinfo\n",
      "    filename = getsourcefile(frame) or getfile(frame)\n",
      "  File \"C:\\Users\\alece\\miniconda3\\envs\\torch\\lib\\inspect.py\", line 693, in getsourcefile\n",
      "    if os.path.exists(filename):\n",
      "  File \"C:\\Users\\alece\\miniconda3\\envs\\torch\\lib\\genericpath.py\", line 19, in exists\n",
      "    os.stat(path)\n",
      "KeyboardInterrupt\n"
     ]
    }
   ],
   "source": [
    "f_rec(-10)"
   ]
  },
  {
   "cell_type": "code",
   "execution_count": 18,
   "id": "c380f009",
   "metadata": {},
   "outputs": [
    {
     "data": {
      "text/plain": [
       "1"
      ]
     },
     "execution_count": 18,
     "metadata": {},
     "output_type": "execute_result"
    }
   ],
   "source": [
    "f_it(-10)"
   ]
  },
  {
   "cell_type": "code",
   "execution_count": 24,
   "id": "e6597341",
   "metadata": {},
   "outputs": [
    {
     "name": "stdout",
     "output_type": "stream",
     "text": [
      "ERROR! Session/line number was not unique in database. History logging moved to new session 837\n"
     ]
    }
   ],
   "source": [
    "lista = ['7', '9', '6', '5', '9', '10', '7', '8', '10', '7', \n",
    "     '7', '6', '6', '10', '6', '6', '7', '10', '9', '10',\n",
    "     '7', '8', '10', '9', '8']\n",
    "         \n",
    "dic = {}\n",
    "\n",
    "for item in lista:\n",
    "    if item not in dic:\n",
    "        dic[item] = 1\n",
    "    else:\n",
    "        dic[item] = dic[item] + 1"
   ]
  },
  {
   "cell_type": "code",
   "execution_count": 25,
   "id": "101ae698",
   "metadata": {},
   "outputs": [
    {
     "data": {
      "text/plain": [
       "{'7': 6, '9': 4, '6': 5, '5': 1, '10': 6, '8': 3}"
      ]
     },
     "execution_count": 25,
     "metadata": {},
     "output_type": "execute_result"
    }
   ],
   "source": [
    "dic"
   ]
  },
  {
   "cell_type": "code",
   "execution_count": null,
   "id": "657acbce",
   "metadata": {},
   "outputs": [],
   "source": [
    "16\n",
    "Ma  -> Mi\n",
    "Re -> not(Re)\n",
    "Mi -> Ale\n",
    "Ale -> "
   ]
  }
 ],
 "metadata": {
  "kernelspec": {
   "display_name": "Python 3",
   "language": "python",
   "name": "python3"
  },
  "language_info": {
   "codemirror_mode": {
    "name": "ipython",
    "version": 3
   },
   "file_extension": ".py",
   "mimetype": "text/x-python",
   "name": "python",
   "nbconvert_exporter": "python",
   "pygments_lexer": "ipython3",
   "version": "3.7.10"
  }
 },
 "nbformat": 4,
 "nbformat_minor": 5
}
